2024-02-26 17:39:33,502 INFO: Microblog startup [in /storage/emulated/0/Acode/microblog/app/__init__.py:31]
2024-02-26 17:39:54,590 INFO: Microblog startup [in /storage/emulated/0/Acode/microblog/app/__init__.py:31]
2024-02-26 17:40:04,892 ERROR: Exception on /edit_profile [GET] [in /data/data/com.termux/files/usr/lib/python3.11/site-packages/flask/app.py:828]
Traceback (most recent call last):
  File "/data/data/com.termux/files/usr/lib/python3.11/site-packages/flask/app.py", line 1463, in wsgi_app
    response = self.full_dispatch_request()
               ^^^^^^^^^^^^^^^^^^^^^^^^^^^^
  File "/data/data/com.termux/files/usr/lib/python3.11/site-packages/flask/app.py", line 872, in full_dispatch_request
    rv = self.handle_user_exception(e)
         ^^^^^^^^^^^^^^^^^^^^^^^^^^^^^
  File "/data/data/com.termux/files/usr/lib/python3.11/site-packages/flask/app.py", line 870, in full_dispatch_request
    rv = self.dispatch_request()
         ^^^^^^^^^^^^^^^^^^^^^^^
  File "/data/data/com.termux/files/usr/lib/python3.11/site-packages/flask/app.py", line 855, in dispatch_request
    return self.ensure_sync(self.view_functions[rule.endpoint])(**view_args)  # type: ignore[no-any-return]
           ^^^^^^^^^^^^^^^^^^^^^^^^^^^^^^^^^^^^^^^^^^^^^^^^^^^^^^^^^^^^^^^^^
  File "/data/data/com.termux/files/usr/lib/python3.11/site-packages/flask_login/utils.py", line 290, in decorated_view
    return current_app.ensure_sync(func)(*args, **kwargs)
           ^^^^^^^^^^^^^^^^^^^^^^^^^^^^^^^^^^^^^^^^^^^^^^
  File "/storage/emulated/0/Acode/microblog/app/routes.py", line 89, in edit_profile
    form = EditProfileForm(current_user.username)
           ^^^^^^^^^^^^^^^^^^^^^^^^^^^^^^^^^^^^^^
  File "/data/data/com.termux/files/usr/lib/python3.11/site-packages/wtforms/form.py", line 208, in __call__
    return type.__call__(cls, *args, **kwargs)
           ^^^^^^^^^^^^^^^^^^^^^^^^^^^^^^^^^^^
  File "/storage/emulated/0/Acode/microblog/app/forms.py", line 36, in __init__
    super(EditProfileForm, self).init(*args, **kwargs)
    ^^^^^^^^^^^^^^^^^^^^^^^^^^^^^^^^^
AttributeError: 'super' object has no attribute 'init'
2024-02-26 17:40:31,157 INFO: Microblog startup [in /storage/emulated/0/Acode/microblog/app/__init__.py:31]
2024-03-17 19:07:23,839 INFO: Microblog startup [in /storage/emulated/0/Acode/microblog/app/__init__.py:31]
2024-03-17 19:10:05,497 INFO: Microblog startup [in /storage/emulated/0/Acode/microblog/app/__init__.py:31]
2024-03-17 19:10:38,281 INFO: Microblog startup [in /storage/emulated/0/Acode/microblog/app/__init__.py:31]
2024-03-19 17:17:36,335 INFO: Microblog startup [in /storage/emulated/0/Acode/microblog/app/__init__.py:31]
2024-03-19 17:18:36,360 INFO: Microblog startup [in /storage/emulated/0/Acode/microblog/app/__init__.py:31]
2024-03-19 17:26:38,621 INFO: Microblog startup [in /storage/emulated/0/Acode/microblog/app/__init__.py:31]
2024-03-19 17:33:41,306 INFO: Microblog startup [in /storage/emulated/0/Acode/microblog/app/__init__.py:31]
2024-03-20 16:15:26,577 INFO: Microblog startup [in /storage/emulated/0/Acode/microblog/app/__init__.py:31]
2024-03-20 16:15:30,901 ERROR: Exception on / [GET] [in /data/data/com.termux/files/usr/lib/python3.11/site-packages/flask/app.py:828]
Traceback (most recent call last):
  File "/data/data/com.termux/files/usr/lib/python3.11/site-packages/sqlalchemy/engine/base.py", line 1969, in _exec_single_context
    self.dialect.do_execute(
  File "/data/data/com.termux/files/usr/lib/python3.11/site-packages/sqlalchemy/engine/default.py", line 922, in do_execute
    cursor.execute(statement, parameters)
sqlite3.OperationalError: no such table: user

The above exception was the direct cause of the following exception:

Traceback (most recent call last):
  File "/data/data/com.termux/files/usr/lib/python3.11/site-packages/flask/app.py", line 1463, in wsgi_app
    response = self.full_dispatch_request()
               ^^^^^^^^^^^^^^^^^^^^^^^^^^^^
  File "/data/data/com.termux/files/usr/lib/python3.11/site-packages/flask/app.py", line 872, in full_dispatch_request
    rv = self.handle_user_exception(e)
         ^^^^^^^^^^^^^^^^^^^^^^^^^^^^^
  File "/data/data/com.termux/files/usr/lib/python3.11/site-packages/flask/app.py", line 868, in full_dispatch_request
    rv = self.preprocess_request()
         ^^^^^^^^^^^^^^^^^^^^^^^^^
  File "/data/data/com.termux/files/usr/lib/python3.11/site-packages/flask/app.py", line 1243, in preprocess_request
    rv = self.ensure_sync(before_func)()
         ^^^^^^^^^^^^^^^^^^^^^^^^^^^^^^^
  File "/storage/emulated/0/Acode/microblog/app/routes.py", line 13, in before_request
    if current_user.is_authenticated:
       ^^^^^^^^^^^^^^^^^^^^^^^^^^^^^
  File "/data/data/com.termux/files/usr/lib/python3.11/site-packages/werkzeug/local.py", line 311, in __get__
    obj = instance._get_current_object()
          ^^^^^^^^^^^^^^^^^^^^^^^^^^^^^^
  File "/data/data/com.termux/files/usr/lib/python3.11/site-packages/werkzeug/local.py", line 515, in _get_current_object
    return get_name(local())
                    ^^^^^^^
  File "/data/data/com.termux/files/usr/lib/python3.11/site-packages/flask_login/utils.py", line 25, in <lambda>
    current_user = LocalProxy(lambda: _get_user())
                                      ^^^^^^^^^^^
  File "/data/data/com.termux/files/usr/lib/python3.11/site-packages/flask_login/utils.py", line 370, in _get_user
    current_app.login_manager._load_user()
  File "/data/data/com.termux/files/usr/lib/python3.11/site-packages/flask_login/login_manager.py", line 376, in _load_user
    user = self._load_user_from_remember_cookie(cookie)
           ^^^^^^^^^^^^^^^^^^^^^^^^^^^^^^^^^^^^^^^^^^^^
  File "/data/data/com.termux/files/usr/lib/python3.11/site-packages/flask_login/login_manager.py", line 420, in _load_user_from_remember_cookie
    user = self._user_callback(user_id)
           ^^^^^^^^^^^^^^^^^^^^^^^^^^^^
  File "/storage/emulated/0/Acode/microblog/app/models.py", line 17, in load_user
    return User.query.get(int(id))
           ^^^^^^^^^^^^^^^^^^^^^^^
  File "<string>", line 2, in get
  File "/data/data/com.termux/files/usr/lib/python3.11/site-packages/sqlalchemy/util/deprecations.py", line 386, in warned
    return fn(*args, **kwargs)  # type: ignore[no-any-return]
           ^^^^^^^^^^^^^^^^^^^
  File "/data/data/com.termux/files/usr/lib/python3.11/site-packages/sqlalchemy/orm/query.py", line 1136, in get
    return self._get_impl(ident, loading.load_on_pk_identity)
           ^^^^^^^^^^^^^^^^^^^^^^^^^^^^^^^^^^^^^^^^^^^^^^^^^^
  File "/data/data/com.termux/files/usr/lib/python3.11/site-packages/sqlalchemy/orm/query.py", line 1145, in _get_impl
    return self.session._get_impl(
           ^^^^^^^^^^^^^^^^^^^^^^^
  File "/data/data/com.termux/files/usr/lib/python3.11/site-packages/sqlalchemy/orm/session.py", line 3833, in _get_impl
    return db_load_fn(
           ^^^^^^^^^^^
  File "/data/data/com.termux/files/usr/lib/python3.11/site-packages/sqlalchemy/orm/loading.py", line 692, in load_on_pk_identity
    session.execute(
  File "/data/data/com.termux/files/usr/lib/python3.11/site-packages/sqlalchemy/orm/session.py", line 2308, in execute
    return self._execute_internal(
           ^^^^^^^^^^^^^^^^^^^^^^^
  File "/data/data/com.termux/files/usr/lib/python3.11/site-packages/sqlalchemy/orm/session.py", line 2190, in _execute_internal
    result: Result[Any] = compile_state_cls.orm_execute_statement(
                          ^^^^^^^^^^^^^^^^^^^^^^^^^^^^^^^^^^^^^^^^
  File "/data/data/com.termux/files/usr/lib/python3.11/site-packages/sqlalchemy/orm/context.py", line 293, in orm_execute_statement
    result = conn.execute(
             ^^^^^^^^^^^^^
  File "/data/data/com.termux/files/usr/lib/python3.11/site-packages/sqlalchemy/engine/base.py", line 1416, in execute
    return meth(
           ^^^^^
  File "/data/data/com.termux/files/usr/lib/python3.11/site-packages/sqlalchemy/sql/elements.py", line 517, in _execute_on_connection
    return connection._execute_clauseelement(
           ^^^^^^^^^^^^^^^^^^^^^^^^^^^^^^^^^^
  File "/data/data/com.termux/files/usr/lib/python3.11/site-packages/sqlalchemy/engine/base.py", line 1639, in _execute_clauseelement
    ret = self._execute_context(
          ^^^^^^^^^^^^^^^^^^^^^^
  File "/data/data/com.termux/files/usr/lib/python3.11/site-packages/sqlalchemy/engine/base.py", line 1848, in _execute_context
    return self._exec_single_context(
           ^^^^^^^^^^^^^^^^^^^^^^^^^^
  File "/data/data/com.termux/files/usr/lib/python3.11/site-packages/sqlalchemy/engine/base.py", line 1988, in _exec_single_context
    self._handle_dbapi_exception(
  File "/data/data/com.termux/files/usr/lib/python3.11/site-packages/sqlalchemy/engine/base.py", line 2344, in _handle_dbapi_exception
    raise sqlalchemy_exception.with_traceback(exc_info[2]) from e
  File "/data/data/com.termux/files/usr/lib/python3.11/site-packages/sqlalchemy/engine/base.py", line 1969, in _exec_single_context
    self.dialect.do_execute(
  File "/data/data/com.termux/files/usr/lib/python3.11/site-packages/sqlalchemy/engine/default.py", line 922, in do_execute
    cursor.execute(statement, parameters)
sqlalchemy.exc.OperationalError: (sqlite3.OperationalError) no such table: user
[SQL: SELECT user.id AS user_id, user.username AS user_username, user.email AS user_email, user.password_hash AS user_password_hash, user.about_me AS user_about_me, user.last_seen AS user_last_seen 
FROM user 
WHERE user.id = ?]
[parameters: (1,)]
(Background on this error at: https://sqlalche.me/e/20/e3q8)
